Workbook

Sheet Weights
A1: Weights: what Stata exported for this run
A2: Every number on this sheet is read from the manifest and the table sheets of the export; nothing is recalculated here (see Notes).
A4: Run
A5: Run id | B5: =IFERROR(INDEX(manifest!$B:$B,MATCH("run_id",manifest!$A:$A,0)),"not in this export")
A6: Workflow | B6: =IFERROR(INDEX(manifest!$B:$B,MATCH("workflow",manifest!$A:$A,0)),"not in this export")
A7: Step | B7: =IFERROR(INDEX(manifest!$B:$B,MATCH("step",manifest!$A:$A,0)),"not in this export")
A8: Started | B8: =IFERROR(INDEX(manifest!$B:$B,MATCH("started",manifest!$A:$A,0)),"not in this export")
A9: Finished | B9: =IFERROR(INDEX(manifest!$B:$B,MATCH("finished",manifest!$A:$A,0)),"not in this export")
A10: Status | B10: =IFERROR(INDEX(manifest!$B:$B,MATCH("status",manifest!$A:$A,0)),"not in this export")
A11: Source (ado or do-file) | B11: =IFERROR(INDEX(manifest!$B:$B,MATCH("source",manifest!$A:$A,0)),"not in this export")
A12: Software | B12: =IFERROR(INDEX(manifest!$B:$B,MATCH("software",manifest!$A:$A,0)),"not in this export")
A13: Input file | B13: =IFERROR(INDEX(manifest!$B:$B,MATCH("input_file",manifest!$A:$A,0)),"not in this export")
A14: Input rows | B14: =IFERROR(INDEX(manifest!$B:$B,MATCH("input_rows",manifest!$A:$A,0)),"not in this export")
A15: Command | B15: =IFERROR(INDEX(manifest!$B:$B,MATCH("command",manifest!$A:$A,0)),"not in this export")
A17: Settings (as recorded by Stata, with the source of the default)
A18: Method | B18: =IFERROR(INDEX(manifest!$B:$B,MATCH("setting_method",manifest!$A:$A,0)),"not in this export")
A19: Method source | B19: =IFERROR(INDEX(manifest!$B:$B,MATCH("source_method",manifest!$A:$A,0)),"not in this export")
A20: Covariates | B20: =IFERROR(INDEX(manifest!$B:$B,MATCH("setting_covariates",manifest!$A:$A,0)),"not in this export")
A21: Classes | B21: =IFERROR(INDEX(manifest!$B:$B,MATCH("setting_classes",manifest!$A:$A,0)),"not in this export")
A22: Cells | B22: =IFERROR(INDEX(manifest!$B:$B,MATCH("setting_cells",manifest!$A:$A,0)),"not in this export")
A23: Moments | B23: =IFERROR(INDEX(manifest!$B:$B,MATCH("setting_moments",manifest!$A:$A,0)),"not in this export")
A24: Propensity groups | B24: =IFERROR(INDEX(manifest!$B:$B,MATCH("setting_ngroups",manifest!$A:$A,0)),"not in this export")
A25: Trimming rule | B25: =IFERROR(INDEX(manifest!$B:$B,MATCH("setting_rule",manifest!$A:$A,0)),"not in this export")
A26: Trimming percentile | B26: =IFERROR(INDEX(manifest!$B:$B,MATCH("setting_pct",manifest!$A:$A,0)),"not in this export")
A27: Calibration engine | B27: =IFERROR(INDEX(manifest!$B:$B,MATCH("setting_engine",manifest!$A:$A,0)),"not in this export")
A28: Calibration variables | B28: =IFERROR(INDEX(manifest!$B:$B,MATCH("setting_calibration_variables",manifest!$A:$A,0)),"not in this export")
A29: Bounds | B29: =IFERROR(INDEX(manifest!$B:$B,MATCH("setting_bounds",manifest!$A:$A,0)),"not in this export")
A30: Input weight | B30: =IFERROR(INDEX(manifest!$B:$B,MATCH("setting_weight",manifest!$A:$A,0)),"not in this export")
A31: New weight | B31: =IFERROR(INDEX(manifest!$B:$B,MATCH("setting_generate",manifest!$A:$A,0)),"not in this export")
A33: Key numbers (r() results of the command)
A34: Eligible sample | B34: =IFERROR(INDEX(manifest!$B:$B,MATCH("summary_N_sample",manifest!$A:$A,0)),"not in this export")
A35: Respondents | B35: =IFERROR(INDEX(manifest!$B:$B,MATCH("summary_N_resp",manifest!$A:$A,0)),"not in this export")
A36: Response rate, unweighted | B36: =IFERROR(INDEX(manifest!$B:$B,MATCH("summary_rr_unweighted",manifest!$A:$A,0)),"not in this export")
A37: Response rate, weighted | B37: =IFERROR(INDEX(manifest!$B:$B,MATCH("summary_rr_weighted",manifest!$A:$A,0)),"not in this export")
A38: Sum of base weights | B38: =IFERROR(INDEX(manifest!$B:$B,MATCH("summary_sum_base",manifest!$A:$A,0)),"not in this export")
A39: Sum of adjusted weights | B39: =IFERROR(INDEX(manifest!$B:$B,MATCH("summary_sum_adj",manifest!$A:$A,0)),"not in this export")
A40: Adjustment factor, min | B40: =IFERROR(INDEX(manifest!$B:$B,MATCH("summary_factor_min",manifest!$A:$A,0)),"not in this export")
A41: Adjustment factor, median | B41: =IFERROR(INDEX(manifest!$B:$B,MATCH("summary_factor_p50",manifest!$A:$A,0)),"not in this export")
A42: Adjustment factor, max | B42: =IFERROR(INDEX(manifest!$B:$B,MATCH("summary_factor_max",manifest!$A:$A,0)),"not in this export")
A43: Largest relative difference to the targets | B43: =IFERROR(INDEX(manifest!$B:$B,MATCH("summary_max_rel_diff",manifest!$A:$A,0)),"not in this export")
...

Sheet Sampling
A1: Sampling: what Stata exported for this run
A2: Sizes, allocation and the draw as computed in Stata; nothing is recalculated here (see Notes).
A4: Run | U4: selected: x | V4: selected: y | W4: not selected: x | X4: not selected: y
A5: Run id | B5: =IFERROR(INDEX(manifest!$B:$B,MATCH("run_id",manifest!$A:$A,0)),"not in this export") | U5: =IF(selection!H2=1,selection!M2,NA()) | V5: =IF(selection!H2=1,selection!N2,NA()) | W5: =IF(selection!H2=0,selection!M2,NA()) | X5: =IF(selection!H2=0,selection!N2,NA())
A6: Step | B6: =IFERROR(INDEX(manifest!$B:$B,MATCH("step",manifest!$A:$A,0)),"not in this export") | U6: =IF(selection!H3=1,selection!M3,NA()) | V6: =IF(selection!H3=1,selection!N3,NA()) | W6: =IF(selection!H3=0,selection!M3,NA()) | X6: =IF(selection!H3=0,selection!N3,NA())
A7: Started | B7: =IFERROR(INDEX(manifest!$B:$B,MATCH("started",manifest!$A:$A,0)),"not in this export") | U7: =IF(selection!H4=1,selection!M4,NA()) | V7: =IF(selection!H4=1,selection!N4,NA()) | W7: =IF(selection!H4=0,selection!M4,NA()) | X7: =IF(selection!H4=0,selection!N4,NA())
A8: Status | B8: =IFERROR(INDEX(manifest!$B:$B,MATCH("status",manifest!$A:$A,0)),"not in this export") | U8: =IF(selection!H5=1,selection!M5,NA()) | V8: =IF(selection!H5=1,selection!N5,NA()) | W8: =IF(selection!H5=0,selection!M5,NA()) | X8: =IF(selection!H5=0,selection!N5,NA())
A9: Source (ado or do-file) | B9: =IFERROR(INDEX(manifest!$B:$B,MATCH("source",manifest!$A:$A,0)),"not in this export") | U9: =IF(selection!H6=1,selection!M6,NA()) | V9: =IF(selection!H6=1,selection!N6,NA()) | W9: =IF(selection!H6=0,selection!M6,NA()) | X9: =IF(selection!H6=0,selection!N6,NA())
A10: Input file | B10: =IFERROR(INDEX(manifest!$B:$B,MATCH("input_file",manifest!$A:$A,0)),"not in this export") | U10: =IF(selection!H7=1,selection!M7,NA()) | V10: =IF(selection!H7=1,selection!N7,NA()) | W10: =IF(selection!H7=0,selection!M7,NA()) | X10: =IF(selection!H7=0,selection!N7,NA())
A11: Input rows | B11: =IFERROR(INDEX(manifest!$B:$B,MATCH("input_rows",manifest!$A:$A,0)),"not in this export") | U11: =IF(selection!H8=1,selection!M8,NA()) | V11: =IF(selection!H8=1,selection!N8,NA()) | W11: =IF(selection!H8=0,selection!M8,NA()) | X11: =IF(selection!H8=0,selection!N8,NA())
A12: Command | B12: =IFERROR(INDEX(manifest!$B:$B,MATCH("command",manifest!$A:$A,0)),"not in this export") | U12: =IF(selection!H9=1,selection!M9,NA()) | V12: =IF(selection!H9=1,selection!N9,NA()) | W12: =IF(selection!H9=0,selection!M9,NA()) | X12: =IF(selection!H9=0,selection!N9,NA())
U13: =IF(selection!H10=1,selection!M10,NA()) | V13: =IF(selection!H10=1,selection!N10,NA()) | W13: =IF(selection!H10=0,selection!M10,NA()) | X13: =IF(selection!H10=0,selection!N10,NA())
A14: Key numbers (r() results of the command) | U14: =IF(selection!H11=1,selection!M11,NA()) | V14: =IF(selection!H11=1,selection!N11,NA()) | W14: =IF(selection!H11=0,selection!M11,NA()) | X14: =IF(selection!H11=0,selection!N11,NA())
A15: Households per domain (size) | B15: =IFERROR(INDEX(manifest!$B:$B,MATCH("summary_n_domain",manifest!$A:$A,0)),"not in this export") | U15: =IF(selection!H12=1,selection!M12,NA()) | V15: =IF(selection!H12=1,selection!N12,NA()) | W15: =IF(selection!H12=0,selection!M12,NA()) | X15: =IF(selection!H12=0,selection!N12,NA())
A16: Households in all domains | B16: =IFERROR(INDEX(manifest!$B:$B,MATCH("summary_n_total",manifest!$A:$A,0)),"not in this export") | U16: =IF(selection!H13=1,selection!M13,NA()) | V16: =IF(selection!H13=1,selection!N13,NA()) | W16: =IF(selection!H13=0,selection!M13,NA()) | X16: =IF(selection!H13=0,selection!N13,NA())
A17: Interviews, simple random sample | B17: =IFERROR(INDEX(manifest!$B:$B,MATCH("summary_n_srs",manifest!$A:$A,0)),"not in this export") | U17: =IF(selection!H14=1,selection!M14,NA()) | V17: =IF(selection!H14=1,selection!N14,NA()) | W17: =IF(selection!H14=0,selection!M14,NA()) | X17: =IF(selection!H14=0,selection!N14,NA())
A18: Attrition reserve factor | B18: =IFERROR(INDEX(manifest!$B:$B,MATCH("summary_f_attrition",manifest!$A:$A,0)),"not in this export") | U18: =IF(selection!H15=1,selection!M15,NA()) | V18: =IF(selection!H15=1,selection!N15,NA()) | W18: =IF(selection!H15=0,selection!M15,NA()) | X18: =IF(selection!H15=0,selection!N15,NA())
A19: Total to allocate | B19: =IFERROR(INDEX(manifest!$B:$B,MATCH("summary_n",manifest!$A:$A,0)),"not in this export") | U19: =IF(selection!H16=1,selection!M16,NA()) | V19: =IF(selection!H16=1,selection!N16,NA()) | W19: =IF(selection!H16=0,selection!M16,NA()) | X19: =IF(selection!H16=0,selection!N16,NA())
A20: Allocated after rounding | B20: =IFERROR(INDEX(manifest!$B:$B,MATCH("summary_n_rounded",manifest!$A:$A,0)),"not in this export") | U20: =IF(selection!H17=1,selection!M17,NA()) | V20: =IF(selection!H17=1,selection!N17,NA()) | W20: =IF(selection!H17=0,selection!M17,NA()) | X20: =IF(selection!H17=0,selection!N17,NA())
A21: Frame units | B21: =IFERROR(INDEX(manifest!$B:$B,MATCH("summary_N_frame",manifest!$A:$A,0)),"not in this export") | U21: =IF(selection!H18=1,selection!M18,NA()) | V21: =IF(selection!H18=1,selection!N18,NA()) | W21: =IF(selection!H18=0,selection!M18,NA()) | X21: =IF(selection!H18=0,selection!N18,NA())
A22: Selected units | B22: =IFERROR(INDEX(manifest!$B:$B,MATCH("summary_n_selected",manifest!$A:$A,0)),"not in this export") | U22: =IF(selection!H19=1,selection!M19,NA()) | V22: =IF(selection!H19=1,selection!N19,NA()) | W22: =IF(selection!H19=0,selection!M19,NA()) | X22: =IF(selection!H19=0,selection!N19,NA())
A23: Reserve units | B23: =IFERROR(INDEX(manifest!$B:$B,MATCH("summary_n_reserve",manifest!$A:$A,0)),"not in this export") | U23: =IF(selection!H20=1,selection!M20,NA()) | V23: =IF(selection!H20=1,selection!N20,NA()) | W23: =IF(selection!H20=0,selection!M20,NA()) | X23: =IF(selection!H20=0,selection!N20,NA())
A24: Certainty units | B24: =IFERROR(INDEX(manifest!$B:$B,MATCH("summary_n_certainty",manifest!$A:$A,0)),"not in this export") | U24: =IF(selection!H21=1,selection!M21,NA()) | V24: =IF(selection!H21=1,selection!N21,NA()) | W24: =IF(selection!H21=0,selection!M21,NA()) | X24: =IF(selection!H21=0,selection!N21,NA())
A25: Strata | B25: =IFERROR(INDEX(manifest!$B:$B,MATCH("summary_H",manifest!$A:$A,0)),"not in this export") | U25: =IF(selection!H22=1,selection!M22,NA()) | V25: =IF(selection!H22=1,selection!N22,NA()) | W25: =IF(selection!H22=0,selection!M22,NA()) | X25: =IF(selection!H22=0,selection!N22,NA())
A26: Seed | B26: =IFERROR(INDEX(manifest!$B:$B,MATCH("summary_seed",manifest!$A:$A,0)),"not in this export") | U26: =IF(selection!H23=1,selection!M23,NA()) | V26: =IF(selection!H23=1,selection!N23,NA()) | W26: =IF(selection!H23=0,selection!M23,NA()) | X26: =IF(selection!H23=0,selection!N23,NA())
A27: Serpentine bands | B27: =IFERROR(INDEX(manifest!$B:$B,MATCH("summary_bands",manifest!$A:$A,0)),"not in this export") | U27: =IF(selection!H24=1,selection!M24,NA()) | V27: =IF(selection!H24=1,selection!N24,NA()) | W27: =IF(selection!H24=0,selection!M24,NA()) | X27: =IF(selection!H24=0,selection!N24,NA())
A28: Numbers generated (RDD) | B28: =IFERROR(INDEX(manifest!$B:$B,MATCH("summary_n_numbers",manifest!$A:$A,0)),"not in this export") | U28: =IF(selection!H25=1,selection!M25,NA()) | V28: =IF(selection!H25=1,selection!N25,NA()) | W28: =IF(selection!H25=0,selection!M25,NA()) | X28: =IF(selection!H25=0,selection!N25,NA())
U29: =IF(selection!H26=1,selection!M26,NA()) | V29: =IF(selection!H26=1,selection!N26,NA()) | W29: =IF(selection!H26=0,selection!M26,NA()) | X29: =IF(selection!H26=0,selection!N26,NA())
A30: Sample size per domain (size.csv) | U30: =IF(selection!H27=1,selection!M27,NA()) | V30: =IF(selection!H27=1,selection!N27,NA()) | W30: =IF(selection!H27=0,selection!M27,NA()) | X30: =IF(selection!H27=0,selection!N27,NA())
A31: domain | B31: p | C31: margin | D31: deff | E31: nonresponse | F31: attrition | G31: rounds | H31: n_effective | I31: n_final | U31: =IF(selection!H28=1,selection!M28,NA()) | V31: =IF(selection!H28=1,selection!N28,NA()) | W31: =IF(selection!H28=0,selection!M28,NA()) | X31: =IF(selection!H28=0,selection!N28,NA())
A32: =IF(size!A2="","",size!A2) | B32: =IF(size!B2="","",size!B2) | C32: =IF(size!C2="","",size!C2) | D32: =IF(size!D2="","",size!D2) | E32: =IF(size!E2="","",size!E2) | F32: =IF(size!F2="","",size!F2) | G32: =IF(size!G2="","",size!G2) | H32: =IF(size!H2="","",size!H2) | I32: =IF(size!I2="","",size!I2) | U32: =IF(selection!H29=1,selection!M29,NA()) | V32: =IF(selection!H29=1,selection!N29,NA()) | W32: =IF(selection!H29=0,selection!M29,NA()) | X32: =IF(selection!H29=0,selection!N29,NA())
A33: =IF(size!A3="","",size!A3) | B33: =IF(size!B3="","",size!B3) | C33: =IF(size!C3="","",size!C3) | D33: =IF(size!D3="","",size!D3) | E33: =IF(size!E3="","",size!E3) | F33: =IF(size!F3="","",size!F3) | G33: =IF(size!G3="","",size!G3) | H33: =IF(size!H3="","",size!H3) | I33: =IF(size!I3="","",size!I3) | U33: =IF(selection!H30=1,selection!M30,NA()) | V33: =IF(selection!H30=1,selection!N30,NA()) | W33: =IF(selection!H30=0,selection!M30,NA()) | X33: =IF(selection!H30=0,selection!N30,NA())
A34: =IF(size!A4="","",size!A4) | B34: =IF(size!B4="","",size!B4) | C34: =IF(size!C4="","",size!C4) | D34: =IF(size!D4="","",size!D4) | E34: =IF(size!E4="","",size!E4) | F34: =IF(size!F4="","",size!F4) | G34: =IF(size!G4="","",size!G4) | H34: =IF(size!H4="","",size!H4) | I34: =IF(size!I4="","",size!I4) | U34: =IF(selection!H31=1,selection!M31,NA()) | V34: =IF(selection!H31=1,selection!N31,NA()) | W34: =IF(selection!H31=0,selection!M31,NA()) | X34: =IF(selection!H31=0,selection!N31,NA())
A35: =IF(size!A5="","",size!A5) | B35: =IF(size!B5="","",size!B5) | C35: =IF(size!C5="","",size!C5) | D35: =IF(size!D5="","",size!D5) | E35: =IF(size!E5="","",size!E5) | F35: =IF(size!F5="","",size!F5) | G35: =IF(size!G5="","",size!G5) | H35: =IF(size!H5="","",size!H5) | I35: =IF(size!I5="","",size!I5) | U35: =IF(selection!H32=1,selection!M32,NA()) | V35: =IF(selection!H32=1,selection!N32,NA()) | W35: =IF(selection!H32=0,selection!M32,NA()) | X35: =IF(selection!H32=0,selection!N32,NA())
A36: =IF(size!A6="","",size!A6) | B36: =IF(size!B6="","",size!B6) | C36: =IF(size!C6="","",size!C6) | D36: =IF(size!D6="","",size!D6) | E36: =IF(size!E6="","",size!E6) | F36: =IF(size!F6="","",size!F6) | G36: =IF(size!G6="","",size!G6) | H36: =IF(size!H6="","",size!H6) | I36: =IF(size!I6="","",size!I6) | U36: =IF(selection!H33=1,selection!M33,NA()) | V36: =IF(selection!H33=1,selection!N33,NA()) | W36: =IF(selection!H33=0,selection!M33,NA()) | X36: =IF(selection!H33=0,selection!N33,NA())
A37: =IF(size!A7="","",size!A7) | B37: =IF(size!B7="","",size!B7) | C37: =IF(size!C7="","",size!C7) | D37: =IF(size!D7="","",size!D7) | E37: =IF(size!E7="","",size!E7) | F37: =IF(size!F7="","",size!F7) | G37: =IF(size!G7="","",size!G7) | H37: =IF(size!H7="","",size!H7) | I37: =IF(size!I7="","",size!I7) | U37: =IF(selection!H34=1,selection!M34,NA()) | V37: =IF(selection!H34=1,selection!N34,NA()) | W37: =IF(selection!H34=0,selection!M34,NA()) | X37: =IF(selection!H34=0,selection!N34,NA())
U38: =IF(selection!H35=1,selection!M35,NA()) | V38: =IF(selection!H35=1,selection!N35,NA()) | W38: =IF(selection!H35=0,selection!M35,NA()) | X38: =IF(selection!H35=0,selection!N35,NA())
A39: Allocation across strata (allocation.csv): planned against final | U39: =IF(selection!H36=1,selection!M36,NA()) | V39: =IF(selection!H36=1,selection!N36,NA()) | W39: =IF(selection!H36=0,selection!M36,NA()) | X39: =IF(selection!H36=0,selection!N36,NA())
A40: stratum | B40: n_units | C40: size_sum | D40: share | E40: n_planned | F40: n_min | G40: n_max | H40: n_final | I40: sampling_fraction | U40: =IF(selection!H37=1,selection!M37,NA()) | V40: =IF(selection!H37=1,selection!N37,NA()) | W40: =IF(selection!H37=0,selection!M37,NA()) | X40: =IF(selection!H37=0,selection!N37,NA())
A41: =IF(allocation!A2="","",allocation!A2) | B41: =IF(allocation!B2="","",allocation!B2) | C41: =IF(allocation!C2="","",allocation!C2) | D41: =IF(allocation!D2="","",allocation!D2) | E41: =IF(allocation!E2="","",allocation!E2) | F41: =IF(allocation!F2="","",allocation!F2) | G41: =IF(allocation!G2="","",allocation!G2) | H41: =IF(allocation!H2="","",allocation!H2) | I41: =IF(allocation!I2="","",allocation!I2) | U41: =IF(selection!H38=1,selection!M38,NA()) | V41: =IF(selection!H38=1,selection!N38,NA()) | W41: =IF(selection!H38=0,selection!M38,NA()) | X41: =IF(selection!H38=0,selection!N38,NA())
...

Sheet Frame
A1: Frame: what Stata exported for this run
A2: List-frame checks or the grid frame as computed in Stata; nothing is recalculated here (see Notes).
A4: Run | U4: units: x | V4: units: y
A5: Run id | B5: =IFERROR(INDEX(manifest!$B:$B,MATCH("run_id",manifest!$A:$A,0)),"not in this export") | U5: =IF(frame_units!E2<>"",frame_units!E2,NA()) | V5: =IF(frame_units!E2<>"",frame_units!F2,NA())
A6: Step | B6: =IFERROR(INDEX(manifest!$B:$B,MATCH("step",manifest!$A:$A,0)),"not in this export") | U6: =IF(frame_units!E3<>"",frame_units!E3,NA()) | V6: =IF(frame_units!E3<>"",frame_units!F3,NA())
A7: Started | B7: =IFERROR(INDEX(manifest!$B:$B,MATCH("started",manifest!$A:$A,0)),"not in this export") | U7: =IF(frame_units!E4<>"",frame_units!E4,NA()) | V7: =IF(frame_units!E4<>"",frame_units!F4,NA())
A8: Status | B8: =IFERROR(INDEX(manifest!$B:$B,MATCH("status",manifest!$A:$A,0)),"not in this export") | U8: =IF(frame_units!E5<>"",frame_units!E5,NA()) | V8: =IF(frame_units!E5<>"",frame_units!F5,NA())
A9: Source (ado or do-file) | B9: =IFERROR(INDEX(manifest!$B:$B,MATCH("source",manifest!$A:$A,0)),"not in this export") | U9: =IF(frame_units!E6<>"",frame_units!E6,NA()) | V9: =IF(frame_units!E6<>"",frame_units!F6,NA())
A10: Input file | B10: =IFERROR(INDEX(manifest!$B:$B,MATCH("input_file",manifest!$A:$A,0)),"not in this export") | U10: =IF(frame_units!E7<>"",frame_units!E7,NA()) | V10: =IF(frame_units!E7<>"",frame_units!F7,NA())
A11: Input rows | B11: =IFERROR(INDEX(manifest!$B:$B,MATCH("input_rows",manifest!$A:$A,0)),"not in this export") | U11: =IF(frame_units!E8<>"",frame_units!E8,NA()) | V11: =IF(frame_units!E8<>"",frame_units!F8,NA())
A12: Command | B12: =IFERROR(INDEX(manifest!$B:$B,MATCH("command",manifest!$A:$A,0)),"not in this export") | U12: =IF(frame_units!E9<>"",frame_units!E9,NA()) | V12: =IF(frame_units!E9<>"",frame_units!F9,NA())
U13: =IF(frame_units!E10<>"",frame_units!E10,NA()) | V13: =IF(frame_units!E10<>"",frame_units!F10,NA())
A14: Key numbers (r() results of the command) | U14: =IF(frame_units!E11<>"",frame_units!E11,NA()) | V14: =IF(frame_units!E11<>"",frame_units!F11,NA())
A15: Units | B15: =IFERROR(INDEX(manifest!$B:$B,MATCH("summary_N",manifest!$A:$A,0)),"not in this export") | U15: =IF(frame_units!E12<>"",frame_units!E12,NA()) | V15: =IF(frame_units!E12<>"",frame_units!F12,NA())
A16: Usable units | B16: =IFERROR(INDEX(manifest!$B:$B,MATCH("summary_N_ok",manifest!$A:$A,0)),"not in this export") | U16: =IF(frame_units!E13<>"",frame_units!E13,NA()) | V16: =IF(frame_units!E13<>"",frame_units!F13,NA())
A17: Duplicate identifiers | B17: =IFERROR(INDEX(manifest!$B:$B,MATCH("summary_n_dup",manifest!$A:$A,0)),"not in this export") | U17: =IF(frame_units!E14<>"",frame_units!E14,NA()) | V17: =IF(frame_units!E14<>"",frame_units!F14,NA())
A18: Bad sizes | B18: =IFERROR(INDEX(manifest!$B:$B,MATCH("summary_n_badsize",manifest!$A:$A,0)),"not in this export") | U18: =IF(frame_units!E15<>"",frame_units!E15,NA()) | V18: =IF(frame_units!E15<>"",frame_units!F15,NA())
A19: Small units or cells | B19: =IFERROR(INDEX(manifest!$B:$B,MATCH("summary_n_small",manifest!$A:$A,0)),"not in this export") | U19: =IF(frame_units!E16<>"",frame_units!E16,NA()) | V19: =IF(frame_units!E16<>"",frame_units!F16,NA())
A20: Large units | B20: =IFERROR(INDEX(manifest!$B:$B,MATCH("summary_n_large",manifest!$A:$A,0)),"not in this export") | U20: =IF(frame_units!E17<>"",frame_units!E17,NA()) | V20: =IF(frame_units!E17<>"",frame_units!F17,NA())
A21: Excluded | B21: =IFERROR(INDEX(manifest!$B:$B,MATCH("summary_n_excluded",manifest!$A:$A,0)),"not in this export") | U21: =IF(frame_units!E18<>"",frame_units!E18,NA()) | V21: =IF(frame_units!E18<>"",frame_units!F18,NA())
A22: Strata | B22: =IFERROR(INDEX(manifest!$B:$B,MATCH("summary_H",manifest!$A:$A,0)),"not in this export") | U22: =IF(frame_units!E19<>"",frame_units!E19,NA()) | V22: =IF(frame_units!E19<>"",frame_units!F19,NA())
A23: Grid cells | B23: =IFERROR(INDEX(manifest!$B:$B,MATCH("summary_N_cells",manifest!$A:$A,0)),"not in this export") | U23: =IF(frame_units!E20<>"",frame_units!E20,NA()) | V23: =IF(frame_units!E20<>"",frame_units!F20,NA())
A24: Boundary polygons | B24: =IFERROR(INDEX(manifest!$B:$B,MATCH("summary_n_polygons",manifest!$A:$A,0)),"not in this export") | U24: =IF(frame_units!E21<>"",frame_units!E21,NA()) | V24: =IF(frame_units!E21<>"",frame_units!F21,NA())
A25: Cells straddling a boundary | B25: =IFERROR(INDEX(manifest!$B:$B,MATCH("summary_n_straddle",manifest!$A:$A,0)),"not in this export") | U25: =IF(frame_units!E22<>"",frame_units!E22,NA()) | V25: =IF(frame_units!E22<>"",frame_units!F22,NA())
A26: Population inside the boundaries | B26: =IFERROR(INDEX(manifest!$B:$B,MATCH("summary_pop_inside",manifest!$A:$A,0)),"not in this export") | U26: =IF(frame_units!E23<>"",frame_units!E23,NA()) | V26: =IF(frame_units!E23<>"",frame_units!F23,NA())
A27: Population outside | B27: =IFERROR(INDEX(manifest!$B:$B,MATCH("summary_pop_outside",manifest!$A:$A,0)),"not in this export") | U27: =IF(frame_units!E24<>"",frame_units!E24,NA()) | V27: =IF(frame_units!E24<>"",frame_units!F24,NA())
A28: Pixels outside | B28: =IFERROR(INDEX(manifest!$B:$B,MATCH("summary_pixels_outside",manifest!$A:$A,0)),"not in this export") | U28: =IF(frame_units!E25<>"",frame_units!E25,NA()) | V28: =IF(frame_units!E25<>"",frame_units!F25,NA())
A29: Cell size (m) | B29: =IFERROR(INDEX(manifest!$B:$B,MATCH("summary_cellsize",manifest!$A:$A,0)),"not in this export") | U29: =IF(frame_units!E26<>"",frame_units!E26,NA()) | V29: =IF(frame_units!E26<>"",frame_units!F26,NA())
A30: Pixel size (m) | B30: =IFERROR(INDEX(manifest!$B:$B,MATCH("summary_pixelsize",manifest!$A:$A,0)),"not in this export") | U30: =IF(frame_units!E27<>"",frame_units!E27,NA()) | V30: =IF(frame_units!E27<>"",frame_units!F27,NA())
A31: Cells with replacement candidates | B31: =IFERROR(INDEX(manifest!$B:$B,MATCH("summary_n_with_candidates",manifest!$A:$A,0)),"not in this export") | U31: =IF(frame_units!E28<>"",frame_units!E28,NA()) | V31: =IF(frame_units!E28<>"",frame_units!F28,NA())
A32: Parts after a split | B32: =IFERROR(INDEX(manifest!$B:$B,MATCH("summary_n_parts",manifest!$A:$A,0)),"not in this export") | U32: =IF(frame_units!E29<>"",frame_units!E29,NA()) | V32: =IF(frame_units!E29<>"",frame_units!F29,NA())
U33: =IF(frame_units!E30<>"",frame_units!E30,NA()) | V33: =IF(frame_units!E30<>"",frame_units!F30,NA())
A34: Summary by stratum (frame_summary.csv) | U34: =IF(frame_units!E31<>"",frame_units!E31,NA()) | V34: =IF(frame_units!E31<>"",frame_units!F31,NA())
A35: stratum | B35: n_units | C35: size_sum | D35: size_min | E35: size_p50 | F35: size_max | G35: n_flagged | U35: =IF(frame_units!E32<>"",frame_units!E32,NA()) | V35: =IF(frame_units!E32<>"",frame_units!F32,NA())
A36: =IF(frame_summary!A2="","",frame_summary!A2) | B36: =IF(frame_summary!B2="","",frame_summary!B2) | C36: =IF(frame_summary!C2="","",frame_summary!C2) | D36: =IF(frame_summary!D2="","",frame_summary!D2) | E36: =IF(frame_summary!E2="","",frame_summary!E2) | F36: =IF(frame_summary!F2="","",frame_summary!F2) | G36: =IF(frame_summary!G2="","",frame_summary!G2) | U36: =IF(frame_units!E33<>"",frame_units!E33,NA()) | V36: =IF(frame_units!E33<>"",frame_units!F33,NA())
A37: =IF(frame_summary!A3="","",frame_summary!A3) | B37: =IF(frame_summary!B3="","",frame_summary!B3) | C37: =IF(frame_summary!C3="","",frame_summary!C3) | D37: =IF(frame_summary!D3="","",frame_summary!D3) | E37: =IF(frame_summary!E3="","",frame_summary!E3) | F37: =IF(frame_summary!F3="","",frame_summary!F3) | G37: =IF(frame_summary!G3="","",frame_summary!G3) | U37: =IF(frame_units!E34<>"",frame_units!E34,NA()) | V37: =IF(frame_units!E34<>"",frame_units!F34,NA())
A38: =IF(frame_summary!A4="","",frame_summary!A4) | B38: =IF(frame_summary!B4="","",frame_summary!B4) | C38: =IF(frame_summary!C4="","",frame_summary!C4) | D38: =IF(frame_summary!D4="","",frame_summary!D4) | E38: =IF(frame_summary!E4="","",frame_summary!E4) | F38: =IF(frame_summary!F4="","",frame_summary!F4) | G38: =IF(frame_summary!G4="","",frame_summary!G4) | U38: =IF(frame_units!E35<>"",frame_units!E35,NA()) | V38: =IF(frame_units!E35<>"",frame_units!F35,NA())
A39: =IF(frame_summary!A5="","",frame_summary!A5) | B39: =IF(frame_summary!B5="","",frame_summary!B5) | C39: =IF(frame_summary!C5="","",frame_summary!C5) | D39: =IF(frame_summary!D5="","",frame_summary!D5) | E39: =IF(frame_summary!E5="","",frame_summary!E5) | F39: =IF(frame_summary!F5="","",frame_summary!F5) | G39: =IF(frame_summary!G5="","",frame_summary!G5) | U39: =IF(frame_units!E36<>"",frame_units!E36,NA()) | V39: =IF(frame_units!E36<>"",frame_units!F36,NA())
A40: =IF(frame_summary!A6="","",frame_summary!A6) | B40: =IF(frame_summary!B6="","",frame_summary!B6) | C40: =IF(frame_summary!C6="","",frame_summary!C6) | D40: =IF(frame_summary!D6="","",frame_summary!D6) | E40: =IF(frame_summary!E6="","",frame_summary!E6) | F40: =IF(frame_summary!F6="","",frame_summary!F6) | G40: =IF(frame_summary!G6="","",frame_summary!G6) | U40: =IF(frame_units!E37<>"",frame_units!E37,NA()) | V40: =IF(frame_units!E37<>"",frame_units!F37,NA())
A41: =IF(frame_summary!A7="","",frame_summary!A7) | B41: =IF(frame_summary!B7="","",frame_summary!B7) | C41: =IF(frame_summary!C7="","",frame_summary!C7) | D41: =IF(frame_summary!D7="","",frame_summary!D7) | E41: =IF(frame_summary!E7="","",frame_summary!E7) | F41: =IF(frame_summary!F7="","",frame_summary!F7) | G41: =IF(frame_summary!G7="","",frame_summary!G7) | U41: =IF(frame_units!E38<>"",frame_units!E38,NA()) | V41: =IF(frame_units!E38<>"",frame_units!F38,NA())
...

Sheet Listing
A1: Listing: what Stata exported for this run
A2: The listing forms and the completed listing's checks as computed in Stata; nothing is recalculated here (see Notes).
A4: Run | U4: areas: x | V4: areas: y
A5: Run id | B5: =IFERROR(INDEX(manifest!$B:$B,MATCH("run_id",manifest!$A:$A,0)),"not in this export") | U5: =IF(listing_areas!C2<>"",listing_areas!C2,NA()) | V5: =IF(listing_areas!C2<>"",listing_areas!D2,NA())
A6: Step | B6: =IFERROR(INDEX(manifest!$B:$B,MATCH("step",manifest!$A:$A,0)),"not in this export") | U6: =IF(listing_areas!C3<>"",listing_areas!C3,NA()) | V6: =IF(listing_areas!C3<>"",listing_areas!D3,NA())
A7: Started | B7: =IFERROR(INDEX(manifest!$B:$B,MATCH("started",manifest!$A:$A,0)),"not in this export") | U7: =IF(listing_areas!C4<>"",listing_areas!C4,NA()) | V7: =IF(listing_areas!C4<>"",listing_areas!D4,NA())
A8: Status | B8: =IFERROR(INDEX(manifest!$B:$B,MATCH("status",manifest!$A:$A,0)),"not in this export") | U8: =IF(listing_areas!C5<>"",listing_areas!C5,NA()) | V8: =IF(listing_areas!C5<>"",listing_areas!D5,NA())
A9: Source (ado or do-file) | B9: =IFERROR(INDEX(manifest!$B:$B,MATCH("source",manifest!$A:$A,0)),"not in this export") | U9: =IF(listing_areas!C6<>"",listing_areas!C6,NA()) | V9: =IF(listing_areas!C6<>"",listing_areas!D6,NA())
A10: Input file | B10: =IFERROR(INDEX(manifest!$B:$B,MATCH("input_file",manifest!$A:$A,0)),"not in this export") | U10: =IF(listing_areas!C7<>"",listing_areas!C7,NA()) | V10: =IF(listing_areas!C7<>"",listing_areas!D7,NA())
A11: Input rows | B11: =IFERROR(INDEX(manifest!$B:$B,MATCH("input_rows",manifest!$A:$A,0)),"not in this export") | U11: =IF(listing_areas!C8<>"",listing_areas!C8,NA()) | V11: =IF(listing_areas!C8<>"",listing_areas!D8,NA())
A12: Command | B12: =IFERROR(INDEX(manifest!$B:$B,MATCH("command",manifest!$A:$A,0)),"not in this export") | U12: =IF(listing_areas!C9<>"",listing_areas!C9,NA()) | V12: =IF(listing_areas!C9<>"",listing_areas!D9,NA())
U13: =IF(listing_areas!C10<>"",listing_areas!C10,NA()) | V13: =IF(listing_areas!C10<>"",listing_areas!D10,NA())
A14: Key numbers (r() results of the command) | U14: =IF(listing_areas!C11<>"",listing_areas!C11,NA()) | V14: =IF(listing_areas!C11<>"",listing_areas!D11,NA())
A15: Selected areas | B15: =IFERROR(INDEX(manifest!$B:$B,MATCH("summary_N_areas",manifest!$A:$A,0)),"not in this export") | U15: =IF(listing_areas!C12<>"",listing_areas!C12,NA()) | V15: =IF(listing_areas!C12<>"",listing_areas!D12,NA())
A16: Areas segmented | B16: =IFERROR(INDEX(manifest!$B:$B,MATCH("summary_n_segmented",manifest!$A:$A,0)),"not in this export") | U16: =IF(listing_areas!C13<>"",listing_areas!C13,NA()) | V16: =IF(listing_areas!C13<>"",listing_areas!D13,NA())
A17: Rows in the listing | B17: =IFERROR(INDEX(manifest!$B:$B,MATCH("summary_N_rows",manifest!$A:$A,0)),"not in this export") | U17: =IF(listing_areas!C14<>"",listing_areas!C14,NA()) | V17: =IF(listing_areas!C14<>"",listing_areas!D14,NA())
A18: Areas returned | B18: =IFERROR(INDEX(manifest!$B:$B,MATCH("summary_n_returned",manifest!$A:$A,0)),"not in this export") | U18: =IF(listing_areas!C15<>"",listing_areas!C15,NA()) | V18: =IF(listing_areas!C15<>"",listing_areas!D15,NA())
A19: Areas not returned | B19: =IFERROR(INDEX(manifest!$B:$B,MATCH("summary_n_not_returned",manifest!$A:$A,0)),"not in this export") | U19: =IF(listing_areas!C16<>"",listing_areas!C16,NA()) | V19: =IF(listing_areas!C16<>"",listing_areas!D16,NA())
A20: Households in areas not selected | B20: =IFERROR(INDEX(manifest!$B:$B,MATCH("summary_n_not_selected",manifest!$A:$A,0)),"not in this export") | U20: =IF(listing_areas!C17<>"",listing_areas!C17,NA()) | V20: =IF(listing_areas!C17<>"",listing_areas!D17,NA())
A21: Duplicate rows | B21: =IFERROR(INDEX(manifest!$B:$B,MATCH("summary_n_duplicates",manifest!$A:$A,0)),"not in this export") | U21: =IF(listing_areas!C18<>"",listing_areas!C18,NA()) | V21: =IF(listing_areas!C18<>"",listing_areas!D18,NA())
A22: Under-listed areas | B22: =IFERROR(INDEX(manifest!$B:$B,MATCH("summary_n_under",manifest!$A:$A,0)),"not in this export") | U22: =IF(listing_areas!C19<>"",listing_areas!C19,NA()) | V22: =IF(listing_areas!C19<>"",listing_areas!D19,NA())
A23: Over-listed areas | B23: =IFERROR(INDEX(manifest!$B:$B,MATCH("summary_n_over",manifest!$A:$A,0)),"not in this export") | U23: =IF(listing_areas!C20<>"",listing_areas!C20,NA()) | V23: =IF(listing_areas!C20<>"",listing_areas!D20,NA())
A24: Eligible households in the frame | B24: =IFERROR(INDEX(manifest!$B:$B,MATCH("summary_N_frame",manifest!$A:$A,0)),"not in this export") | U24: =IF(listing_areas!C21<>"",listing_areas!C21,NA()) | V24: =IF(listing_areas!C21<>"",listing_areas!D21,NA())
U25: =IF(listing_areas!C22<>"",listing_areas!C22,NA()) | V25: =IF(listing_areas!C22<>"",listing_areas!D22,NA())
A26: Checks (listing_checks.csv) | U26: =IF(listing_areas!C23<>"",listing_areas!C23,NA()) | V26: =IF(listing_areas!C23<>"",listing_areas!D23,NA())
A27: check | B27: n | C27: status | D27: detail | U27: =IF(listing_areas!C24<>"",listing_areas!C24,NA()) | V27: =IF(listing_areas!C24<>"",listing_areas!D24,NA())
A28: =IF(listing_checks!A2="","",listing_checks!A2) | B28: =IF(listing_checks!B2="","",listing_checks!B2) | C28: =IF(listing_checks!C2="","",listing_checks!C2) | D28: =IF(listing_checks!D2="","",listing_checks!D2) | U28: =IF(listing_areas!C25<>"",listing_areas!C25,NA()) | V28: =IF(listing_areas!C25<>"",listing_areas!D25,NA())
A29: =IF(listing_checks!A3="","",listing_checks!A3) | B29: =IF(listing_checks!B3="","",listing_checks!B3) | C29: =IF(listing_checks!C3="","",listing_checks!C3) | D29: =IF(listing_checks!D3="","",listing_checks!D3) | U29: =IF(listing_areas!C26<>"",listing_areas!C26,NA()) | V29: =IF(listing_areas!C26<>"",listing_areas!D26,NA())
A30: =IF(listing_checks!A4="","",listing_checks!A4) | B30: =IF(listing_checks!B4="","",listing_checks!B4) | C30: =IF(listing_checks!C4="","",listing_checks!C4) | D30: =IF(listing_checks!D4="","",listing_checks!D4) | U30: =IF(listing_areas!C27<>"",listing_areas!C27,NA()) | V30: =IF(listing_areas!C27<>"",listing_areas!D27,NA())
A31: =IF(listing_checks!A5="","",listing_checks!A5) | B31: =IF(listing_checks!B5="","",listing_checks!B5) | C31: =IF(listing_checks!C5="","",listing_checks!C5) | D31: =IF(listing_checks!D5="","",listing_checks!D5) | U31: =IF(listing_areas!C28<>"",listing_areas!C28,NA()) | V31: =IF(listing_areas!C28<>"",listing_areas!D28,NA())
A32: =IF(listing_checks!A6="","",listing_checks!A6) | B32: =IF(listing_checks!B6="","",listing_checks!B6) | C32: =IF(listing_checks!C6="","",listing_checks!C6) | D32: =IF(listing_checks!D6="","",listing_checks!D6) | U32: =IF(listing_areas!C29<>"",listing_areas!C29,NA()) | V32: =IF(listing_areas!C29<>"",listing_areas!D29,NA())
A33: =IF(listing_checks!A7="","",listing_checks!A7) | B33: =IF(listing_checks!B7="","",listing_checks!B7) | C33: =IF(listing_checks!C7="","",listing_checks!C7) | D33: =IF(listing_checks!D7="","",listing_checks!D7) | U33: =IF(listing_areas!C30<>"",listing_areas!C30,NA()) | V33: =IF(listing_areas!C30<>"",listing_areas!D30,NA())
A34: =IF(listing_checks!A8="","",listing_checks!A8) | B34: =IF(listing_checks!B8="","",listing_checks!B8) | C34: =IF(listing_checks!C8="","",listing_checks!C8) | D34: =IF(listing_checks!D8="","",listing_checks!D8) | U34: =IF(listing_areas!C31<>"",listing_areas!C31,NA()) | V34: =IF(listing_areas!C31<>"",listing_areas!D31,NA())
A35: =IF(listing_checks!A9="","",listing_checks!A9) | B35: =IF(listing_checks!B9="","",listing_checks!B9) | C35: =IF(listing_checks!C9="","",listing_checks!C9) | D35: =IF(listing_checks!D9="","",listing_checks!D9) | U35: =IF(listing_areas!C32<>"",listing_areas!C32,NA()) | V35: =IF(listing_areas!C32<>"",listing_areas!D32,NA())
A36: =IF(listing_checks!A10="","",listing_checks!A10) | B36: =IF(listing_checks!B10="","",listing_checks!B10) | C36: =IF(listing_checks!C10="","",listing_checks!C10) | D36: =IF(listing_checks!D10="","",listing_checks!D10) | U36: =IF(listing_areas!C33<>"",listing_areas!C33,NA()) | V36: =IF(listing_areas!C33<>"",listing_areas!D33,NA())
A37: =IF(listing_checks!A11="","",listing_checks!A11) | B37: =IF(listing_checks!B11="","",listing_checks!B11) | C37: =IF(listing_checks!C11="","",listing_checks!C11) | D37: =IF(listing_checks!D11="","",listing_checks!D11) | U37: =IF(listing_areas!C34<>"",listing_areas!C34,NA()) | V37: =IF(listing_areas!C34<>"",listing_areas!D34,NA())
A38: =IF(listing_checks!A12="","",listing_checks!A12) | B38: =IF(listing_checks!B12="","",listing_checks!B12) | C38: =IF(listing_checks!C12="","",listing_checks!C12) | D38: =IF(listing_checks!D12="","",listing_checks!D12) | U38: =IF(listing_areas!C35<>"",listing_areas!C35,NA()) | V38: =IF(listing_areas!C35<>"",listing_areas!D35,NA())
A39: =IF(listing_checks!A13="","",listing_checks!A13) | B39: =IF(listing_checks!B13="","",listing_checks!B13) | C39: =IF(listing_checks!C13="","",listing_checks!C13) | D39: =IF(listing_checks!D13="","",listing_checks!D13) | U39: =IF(listing_areas!C36<>"",listing_areas!C36,NA()) | V39: =IF(listing_areas!C36<>"",listing_areas!D36,NA())
U40: =IF(listing_areas!C37<>"",listing_areas!C37,NA()) | V40: =IF(listing_areas!C37<>"",listing_areas!D37,NA())
A41: Areas (listing_areas.csv, first 100 rows) | U41: =IF(listing_areas!C38<>"",listing_areas!C38,NA()) | V41: =IF(listing_areas!C38<>"",listing_areas!D38,NA())
...

Sheet Inputs
A1: Inputs: the checks rtminput made on the input workbook
A2: The Design settings as recorded and every problem found, sheet by sheet; nothing is recalculated here (see Notes).
A4: Run
A5: Run id | B5: =IFERROR(INDEX(manifest!$B:$B,MATCH("run_id",manifest!$A:$A,0)),"not in this export")
A6: Step | B6: =IFERROR(INDEX(manifest!$B:$B,MATCH("step",manifest!$A:$A,0)),"not in this export")
A7: Started | B7: =IFERROR(INDEX(manifest!$B:$B,MATCH("started",manifest!$A:$A,0)),"not in this export")
A8: Status | B8: =IFERROR(INDEX(manifest!$B:$B,MATCH("status",manifest!$A:$A,0)),"not in this export")
A9: Source (ado or do-file) | B9: =IFERROR(INDEX(manifest!$B:$B,MATCH("source",manifest!$A:$A,0)),"not in this export")
A10: Input file | B10: =IFERROR(INDEX(manifest!$B:$B,MATCH("input_file",manifest!$A:$A,0)),"not in this export")
A11: Input rows | B11: =IFERROR(INDEX(manifest!$B:$B,MATCH("input_rows",manifest!$A:$A,0)),"not in this export")
A12: Command | B12: =IFERROR(INDEX(manifest!$B:$B,MATCH("command",manifest!$A:$A,0)),"not in this export")
A14: Design settings (as recorded by Stata from the Design sheet)
A15: Project | B15: =IFERROR(INDEX(manifest!$B:$B,MATCH("setting_project",manifest!$A:$A,0)),"not in this export")
A16: Seed | B16: =IFERROR(INDEX(manifest!$B:$B,MATCH("setting_seed",manifest!$A:$A,0)),"not in this export")
A17: Output folder | B17: =IFERROR(INDEX(manifest!$B:$B,MATCH("setting_output_dir",manifest!$A:$A,0)),"not in this export")
A18: Size target | B18: =IFERROR(INDEX(manifest!$B:$B,MATCH("setting_target",manifest!$A:$A,0)),"not in this export")
A19: Areas to select | B19: =IFERROR(INDEX(manifest!$B:$B,MATCH("setting_n_areas",manifest!$A:$A,0)),"not in this export")
A20: Allocation | B20: =IFERROR(INDEX(manifest!$B:$B,MATCH("setting_allocation",manifest!$A:$A,0)),"not in this export")
A21: First stage | B21: =IFERROR(INDEX(manifest!$B:$B,MATCH("setting_stage1",manifest!$A:$A,0)),"not in this export")
A22: Reserve areas | B22: =IFERROR(INDEX(manifest!$B:$B,MATCH("setting_reserve_areas",manifest!$A:$A,0)),"not in this export")
A23: Households per area | B23: =IFERROR(INDEX(manifest!$B:$B,MATCH("setting_households_per_area",manifest!$A:$A,0)),"not in this export")
A24: Phone per PSU | B24: =IFERROR(INDEX(manifest!$B:$B,MATCH("setting_phone_per_psu",manifest!$A:$A,0)),"not in this export")
A25: Base weight | B25: =IFERROR(INDEX(manifest!$B:$B,MATCH("setting_base_weight",manifest!$A:$A,0)),"not in this export")
A26: Nonresponse method | B26: =IFERROR(INDEX(manifest!$B:$B,MATCH("setting_nonresponse",manifest!$A:$A,0)),"not in this export")
A27: Covariates | B27: =IFERROR(INDEX(manifest!$B:$B,MATCH("setting_covariates",manifest!$A:$A,0)),"not in this export")
A28: Trimming | B28: =IFERROR(INDEX(manifest!$B:$B,MATCH("setting_trim",manifest!$A:$A,0)),"not in this export")
A29: Calibration | B29: =IFERROR(INDEX(manifest!$B:$B,MATCH("setting_calibrate",manifest!$A:$A,0)),"not in this export")
A30: Calibration variables | B30: =IFERROR(INDEX(manifest!$B:$B,MATCH("setting_cal_vars",manifest!$A:$A,0)),"not in this export")
A32: Problems found (input_checks.csv; the Checks sheet of the checked copy holds the same rows)
A33: sheet | B33: row | C33: column | D33: severity | E33: problem
A34: =IF(input_checks!A2="","",input_checks!A2) | B34: =IF(input_checks!B2="","",input_checks!B2) | C34: =IF(input_checks!C2="","",input_checks!C2) | D34: =IF(input_checks!D2="","",input_checks!D2) | E34: =IF(input_checks!E2="","",input_checks!E2)
A35: =IF(input_checks!A3="","",input_checks!A3) | B35: =IF(input_checks!B3="","",input_checks!B3) | C35: =IF(input_checks!C3="","",input_checks!C3) | D35: =IF(input_checks!D3="","",input_checks!D3) | E35: =IF(input_checks!E3="","",input_checks!E3)
A36: =IF(input_checks!A4="","",input_checks!A4) | B36: =IF(input_checks!B4="","",input_checks!B4) | C36: =IF(input_checks!C4="","",input_checks!C4) | D36: =IF(input_checks!D4="","",input_checks!D4) | E36: =IF(input_checks!E4="","",input_checks!E4)
A37: =IF(input_checks!A5="","",input_checks!A5) | B37: =IF(input_checks!B5="","",input_checks!B5) | C37: =IF(input_checks!C5="","",input_checks!C5) | D37: =IF(input_checks!D5="","",input_checks!D5) | E37: =IF(input_checks!E5="","",input_checks!E5)
A38: =IF(input_checks!A6="","",input_checks!A6) | B38: =IF(input_checks!B6="","",input_checks!B6) | C38: =IF(input_checks!C6="","",input_checks!C6) | D38: =IF(input_checks!D6="","",input_checks!D6) | E38: =IF(input_checks!E6="","",input_checks!E6)
A39: =IF(input_checks!A7="","",input_checks!A7) | B39: =IF(input_checks!B7="","",input_checks!B7) | C39: =IF(input_checks!C7="","",input_checks!C7) | D39: =IF(input_checks!D7="","",input_checks!D7) | E39: =IF(input_checks!E7="","",input_checks!E7)
A40: =IF(input_checks!A8="","",input_checks!A8) | B40: =IF(input_checks!B8="","",input_checks!B8) | C40: =IF(input_checks!C8="","",input_checks!C8) | D40: =IF(input_checks!D8="","",input_checks!D8) | E40: =IF(input_checks!E8="","",input_checks!E8)
A41: =IF(input_checks!A9="","",input_checks!A9) | B41: =IF(input_checks!B9="","",input_checks!B9) | C41: =IF(input_checks!C9="","",input_checks!C9) | D41: =IF(input_checks!D9="","",input_checks!D9) | E41: =IF(input_checks!E9="","",input_checks!E9)
A42: =IF(input_checks!A10="","",input_checks!A10) | B42: =IF(input_checks!B10="","",input_checks!B10) | C42: =IF(input_checks!C10="","",input_checks!C10) | D42: =IF(input_checks!D10="","",input_checks!D10) | E42: =IF(input_checks!E10="","",input_checks!E10)
A43: =IF(input_checks!A11="","",input_checks!A11) | B43: =IF(input_checks!B11="","",input_checks!B11) | C43: =IF(input_checks!C11="","",input_checks!C11) | D43: =IF(input_checks!D11="","",input_checks!D11) | E43: =IF(input_checks!E11="","",input_checks!E11)
...

Sheet Notes
A1: rtmtools display workbook (schema rtm-export-1.0)
A2: This workbook displays what the Stata commands exported for one run (sheets Weights, Sampling, Frame, Listing, Inputs; use the one of the run's
A3: workflow). Stata copies this template into the run folder and fills the sheet
A4: 'manifest' and one sheet per export table (weight_stages, response_classes, calibration_fit, weight_groups, flags, ...) from the same
A5: CSV files that the dashboard reads. Nothing in this workbook recalculates a statistic: every value on the Weights sheet is a reference
A6: or a lookup into those sheets, and every chart plots a column of them.
A8: Formulas used, the complete list: IF, IFERROR, INDEX, MATCH, COUNTIF, COUNTA, NA. IF only blanks out empty rows; IFERROR, INDEX and MATCH
A9: fetch a value from the manifest; COUNTIF and COUNTA count exported rows; NA() keeps a point off a scatter chart (the map helper
A10: columns U to X of the Sampling, Frame and Listing sheets). No division, multiplication, power, RAND, PERCENTILE, STDEV, Solver or
A11: Analysis ToolPak anywhere. tests/check_display.py reads every formula and fails on any other function.
A13: Rounding: values are stored exactly as exported; number formats show three decimals (counts as integers).
A14: 'not in this export' means the step did not produce that value or table.
... A18: sheets of the same name, or paste the CSV contents into them; the Weights sheet then shows them. Nothing leaves this computer.

Sheet manifest
A1: key | B1: value

Sheet frame_units
A1: unit_id | B1: stratum | C1: unit | D1: size | E1: x | F1: y | G1: flag

Sheet frame_summary
A1: stratum | B1: n_units | C1: size_sum | D1: size_min | E1: size_p50 | F1: size_max | G1: n_flagged

Sheet boundaries
A1: polygon_id | B1: part | C1: vertex | D1: x | E1: y

Sheet listing_areas
A1: area_id | B1: stratum | C1: expected | D1: listed | E1: eligible | F1: ratio | G1: segments | H1: segment_selected | I1: flag

Sheet listing_checks
A1: check | B1: n | C1: status | D1: detail

Sheet size
A1: domain | B1: p | C1: margin | D1: deff | E1: nonresponse | F1: attrition | G1: rounds | H1: n_effective | I1: n_final

Sheet allocation
A1: stratum | B1: n_units | C1: size_sum | D1: share | E1: n_planned | F1: n_min | G1: n_max | H1: n_final | I1: sampling_fraction

Sheet selection
A1: unit_id | B1: stratum | C1: size | D1: order | E1: key | F1: cum_size | G1: selection_number | H1: selected | I1: reserve | J1: rank | K1: prob | L1: weight | M1: x | N1: y

Sheet draw_summary
A1: stratum | B1: n_units | C1: n_selected | D1: n_reserve | E1: prob_min | F1: prob_max | G1: interval | H1: random_start

Sheet weight_stages
A1: stage | B1: variable | C1: n | D1: sum | E1: min | F1: p1 | G1: p5 | H1: p25 | I1: p50 | J1: p75 | K1: p95 | L1: p99 | M1: max | N1: mean | O1: cv | P1: kish_deff | Q1: n_trimmed | R1: n_zero

Sheet weight_groups
A1: stage | B1: variable | C1: group_var | D1: group | E1: n | F1: sum | G1: mean | H1: cv

Sheet response_classes
A1: class_var | B1: class | C1: n_sample | D1: n_respondents | E1: response_rate | F1: factor

Sheet calibration_fit
A1: constraint | B1: target | C1: before | D1: after | E1: diff | F1: rel_diff | G1: converged | H1: iterations

Sheet weight_units
A1: unit_id | B1: stratum | C1: psu | D1: flag

Sheet flags
A1: table | B1: unit_id | C1: stage | D1: value | E1: reason

Sheet replacements
A1: unit_id | B1: candidate_id | C1: rank | D1: distance | E1: stratum | F1: adjacency

Sheet input_checks
A1: sheet | B1: row | C1: column | D1: severity | E1: problem
